2023-07-18 21:41:17,382 django.utils.autoreload INFO     Watching for file changes with StatReloader
2023-07-18 21:41:40,305 django.request WARNING  Bad Request: /api/user/user_registration
2023-07-18 21:42:48,962 django.request WARNING  Bad Request: /api/user/user_registration
2023-07-18 21:44:13,363 django.utils.autoreload INFO     Watching for file changes with StatReloader
2023-07-18 21:44:31,801 labor_hours_dev ERROR    the message that should be logged
2023-07-18 21:44:31,805 django.request WARNING  Bad Request: /api/user/user_registration
2023-07-18 21:44:45,566 django.utils.autoreload INFO     /Users/tmy/Desktop/WatchTogether/users/backend_logic.py changed, reloading.
2023-07-18 21:44:45,741 django.utils.autoreload INFO     Watching for file changes with StatReloader
2023-07-18 21:44:54,190 django.request WARNING  Bad Request: /api/user/user_registration
2023-07-18 21:45:10,303 django.request WARNING  Bad Request: /api/user/user_registration
2023-07-18 21:45:52,160 django.utils.autoreload INFO     /Users/tmy/Desktop/WatchTogether/users/backend_logic.py changed, reloading.
2023-07-18 21:45:52,332 django.utils.autoreload INFO     Watching for file changes with StatReloader
2023-07-18 21:48:35,198 django.utils.autoreload INFO     /Users/tmy/Desktop/WatchTogether/users/backend_logic.py changed, reloading.
2023-07-18 21:48:35,386 django.utils.autoreload INFO     Watching for file changes with StatReloader
2023-07-18 21:50:16,965 django.utils.autoreload INFO     /Users/tmy/Desktop/WatchTogether/users/backend_logic.py changed, reloading.
2023-07-18 21:50:17,137 django.utils.autoreload INFO     Watching for file changes with StatReloader
2023-07-18 21:51:17,311 django.utils.autoreload INFO     /Users/tmy/Desktop/WatchTogether/users/backend_logic.py changed, reloading.
2023-07-18 21:51:17,487 django.utils.autoreload INFO     Watching for file changes with StatReloader
2023-07-18 21:51:59,050 django.utils.autoreload INFO     /Users/tmy/Desktop/WatchTogether/users/backend_logic.py changed, reloading.
2023-07-18 21:51:59,229 django.utils.autoreload INFO     Watching for file changes with StatReloader
2023-07-18 21:52:32,842 django.request ERROR    Internal Server Error: /api/user/activate/ZnVsbCB0ZXN0/brjzf0-512f8f12a0cbd60fe6ce3303f9a1a1f2
Traceback (most recent call last):
  File "/Users/tmy/Desktop/WatchTogether/venv/lib/python3.11/site-packages/django/db/models/fields/__init__.py", line 2053, in get_prep_value
    return int(value)
           ^^^^^^^^^^
ValueError: invalid literal for int() with base 10: 'golqmDIkk'

The above exception was the direct cause of the following exception:

Traceback (most recent call last):
  File "/Users/tmy/Desktop/WatchTogether/venv/lib/python3.11/site-packages/django/core/handlers/exception.py", line 55, in inner
    response = get_response(request)
               ^^^^^^^^^^^^^^^^^^^^^
  File "/Users/tmy/Desktop/WatchTogether/venv/lib/python3.11/site-packages/django/core/handlers/base.py", line 197, in _get_response
    response = wrapped_callback(request, *callback_args, **callback_kwargs)
               ^^^^^^^^^^^^^^^^^^^^^^^^^^^^^^^^^^^^^^^^^^^^^^^^^^^^^^^^^^^^
  File "/Users/tmy/Desktop/WatchTogether/users/backend_logic.py", line 49, in activate
    user = User.objects.filter(pk=username)
           ^^^^^^^^^^^^^^^^^^^^^^^^^^^^^^^^
  File "/Users/tmy/Desktop/WatchTogether/venv/lib/python3.11/site-packages/django/db/models/manager.py", line 87, in manager_method
    return getattr(self.get_queryset(), name)(*args, **kwargs)
           ^^^^^^^^^^^^^^^^^^^^^^^^^^^^^^^^^^^^^^^^^^^^^^^^^^^
  File "/Users/tmy/Desktop/WatchTogether/venv/lib/python3.11/site-packages/django/db/models/query.py", line 1436, in filter
    return self._filter_or_exclude(False, args, kwargs)
           ^^^^^^^^^^^^^^^^^^^^^^^^^^^^^^^^^^^^^^^^^^^^
  File "/Users/tmy/Desktop/WatchTogether/venv/lib/python3.11/site-packages/django/db/models/query.py", line 1454, in _filter_or_exclude
    clone._filter_or_exclude_inplace(negate, args, kwargs)
  File "/Users/tmy/Desktop/WatchTogether/venv/lib/python3.11/site-packages/django/db/models/query.py", line 1461, in _filter_or_exclude_inplace
    self._query.add_q(Q(*args, **kwargs))
  File "/Users/tmy/Desktop/WatchTogether/venv/lib/python3.11/site-packages/django/db/models/sql/query.py", line 1534, in add_q
    clause, _ = self._add_q(q_object, self.used_aliases)
                ^^^^^^^^^^^^^^^^^^^^^^^^^^^^^^^^^^^^^^^^
  File "/Users/tmy/Desktop/WatchTogether/venv/lib/python3.11/site-packages/django/db/models/sql/query.py", line 1565, in _add_q
    child_clause, needed_inner = self.build_filter(
                                 ^^^^^^^^^^^^^^^^^^
  File "/Users/tmy/Desktop/WatchTogether/venv/lib/python3.11/site-packages/django/db/models/sql/query.py", line 1480, in build_filter
    condition = self.build_lookup(lookups, col, value)
                ^^^^^^^^^^^^^^^^^^^^^^^^^^^^^^^^^^^^^^
  File "/Users/tmy/Desktop/WatchTogether/venv/lib/python3.11/site-packages/django/db/models/sql/query.py", line 1307, in build_lookup
    lookup = lookup_class(lhs, rhs)
             ^^^^^^^^^^^^^^^^^^^^^^
  File "/Users/tmy/Desktop/WatchTogether/venv/lib/python3.11/site-packages/django/db/models/lookups.py", line 27, in __init__
    self.rhs = self.get_prep_lookup()
               ^^^^^^^^^^^^^^^^^^^^^^
  File "/Users/tmy/Desktop/WatchTogether/venv/lib/python3.11/site-packages/django/db/models/lookups.py", line 341, in get_prep_lookup
    return super().get_prep_lookup()
           ^^^^^^^^^^^^^^^^^^^^^^^^^
  File "/Users/tmy/Desktop/WatchTogether/venv/lib/python3.11/site-packages/django/db/models/lookups.py", line 85, in get_prep_lookup
    return self.lhs.output_field.get_prep_value(self.rhs)
           ^^^^^^^^^^^^^^^^^^^^^^^^^^^^^^^^^^^^^^^^^^^^^^
  File "/Users/tmy/Desktop/WatchTogether/venv/lib/python3.11/site-packages/django/db/models/fields/__init__.py", line 2055, in get_prep_value
    raise e.__class__(
ValueError: Field 'id' expected a number but got 'golqmDIkk'.
2023-07-18 21:53:52,335 django.utils.autoreload INFO     /Users/tmy/Desktop/WatchTogether/users/backend_logic.py changed, reloading.
2023-07-18 21:53:52,525 django.utils.autoreload INFO     Watching for file changes with StatReloader
2023-07-18 22:06:22,527 django.utils.autoreload INFO     Watching for file changes with StatReloader
2023-07-18 22:06:28,384 django.request ERROR    Internal Server Error: /api/user/user_registration
Traceback (most recent call last):
  File "/Users/tmy/Desktop/WatchTogether/venv/lib/python3.11/site-packages/django/core/handlers/exception.py", line 55, in inner
    response = get_response(request)
               ^^^^^^^^^^^^^^^^^^^^^
  File "/Users/tmy/Desktop/WatchTogether/venv/lib/python3.11/site-packages/django/core/handlers/base.py", line 197, in _get_response
    response = wrapped_callback(request, *callback_args, **callback_kwargs)
               ^^^^^^^^^^^^^^^^^^^^^^^^^^^^^^^^^^^^^^^^^^^^^^^^^^^^^^^^^^^^
  File "/Users/tmy/Desktop/WatchTogether/venv/lib/python3.11/site-packages/django/views/decorators/csrf.py", line 56, in wrapper_view
    return view_func(*args, **kwargs)
           ^^^^^^^^^^^^^^^^^^^^^^^^^^
  File "/Users/tmy/Desktop/WatchTogether/venv/lib/python3.11/site-packages/django/views/generic/base.py", line 104, in view
    return self.dispatch(request, *args, **kwargs)
           ^^^^^^^^^^^^^^^^^^^^^^^^^^^^^^^^^^^^^^^
  File "/Users/tmy/Desktop/WatchTogether/venv/lib/python3.11/site-packages/rest_framework/views.py", line 509, in dispatch
    response = self.handle_exception(exc)
               ^^^^^^^^^^^^^^^^^^^^^^^^^^
  File "/Users/tmy/Desktop/WatchTogether/venv/lib/python3.11/site-packages/rest_framework/views.py", line 469, in handle_exception
    self.raise_uncaught_exception(exc)
  File "/Users/tmy/Desktop/WatchTogether/venv/lib/python3.11/site-packages/rest_framework/views.py", line 480, in raise_uncaught_exception
    raise exc
  File "/Users/tmy/Desktop/WatchTogether/venv/lib/python3.11/site-packages/rest_framework/views.py", line 506, in dispatch
    response = handler(request, *args, **kwargs)
               ^^^^^^^^^^^^^^^^^^^^^^^^^^^^^^^^^
  File "/Users/tmy/Desktop/WatchTogether/users/views.py", line 16, in post
    return Response(data=msg.data, status=status.HTTP_200_OK)
                         ^^^^^^^^
AttributeError: 'NoneType' object has no attribute 'data'
2023-07-18 22:06:37,183 django.utils.autoreload INFO     /Users/tmy/Desktop/WatchTogether/users/views.py changed, reloading.
2023-07-18 22:06:37,373 django.utils.autoreload INFO     Watching for file changes with StatReloader
2023-07-18 22:07:19,306 django.request ERROR    Internal Server Error: /api/user/activate/TWl0aW9QaXNodG92YTY5MzY5/brk035-bdbd1b5748e9e28823451ac9b91e9d92
Traceback (most recent call last):
  File "/Users/tmy/Desktop/WatchTogether/venv/lib/python3.11/site-packages/django/db/models/fields/__init__.py", line 2053, in get_prep_value
    return int(value)
           ^^^^^^^^^^
ValueError: invalid literal for int() with base 10: 'golqmDIkk'

The above exception was the direct cause of the following exception:

Traceback (most recent call last):
  File "/Users/tmy/Desktop/WatchTogether/venv/lib/python3.11/site-packages/django/core/handlers/exception.py", line 55, in inner
    response = get_response(request)
               ^^^^^^^^^^^^^^^^^^^^^
  File "/Users/tmy/Desktop/WatchTogether/venv/lib/python3.11/site-packages/django/core/handlers/base.py", line 197, in _get_response
    response = wrapped_callback(request, *callback_args, **callback_kwargs)
               ^^^^^^^^^^^^^^^^^^^^^^^^^^^^^^^^^^^^^^^^^^^^^^^^^^^^^^^^^^^^
  File "/Users/tmy/Desktop/WatchTogether/users/backend_logic.py", line 42, in activate
    user = User.objects.filter(pk=username)
           ^^^^^^^^^^^^^^^^^^^^^^^^^^^^^^^^
  File "/Users/tmy/Desktop/WatchTogether/venv/lib/python3.11/site-packages/django/db/models/manager.py", line 87, in manager_method
    return getattr(self.get_queryset(), name)(*args, **kwargs)
           ^^^^^^^^^^^^^^^^^^^^^^^^^^^^^^^^^^^^^^^^^^^^^^^^^^^
  File "/Users/tmy/Desktop/WatchTogether/venv/lib/python3.11/site-packages/django/db/models/query.py", line 1436, in filter
    return self._filter_or_exclude(False, args, kwargs)
           ^^^^^^^^^^^^^^^^^^^^^^^^^^^^^^^^^^^^^^^^^^^^
  File "/Users/tmy/Desktop/WatchTogether/venv/lib/python3.11/site-packages/django/db/models/query.py", line 1454, in _filter_or_exclude
    clone._filter_or_exclude_inplace(negate, args, kwargs)
  File "/Users/tmy/Desktop/WatchTogether/venv/lib/python3.11/site-packages/django/db/models/query.py", line 1461, in _filter_or_exclude_inplace
    self._query.add_q(Q(*args, **kwargs))
  File "/Users/tmy/Desktop/WatchTogether/venv/lib/python3.11/site-packages/django/db/models/sql/query.py", line 1534, in add_q
    clause, _ = self._add_q(q_object, self.used_aliases)
                ^^^^^^^^^^^^^^^^^^^^^^^^^^^^^^^^^^^^^^^^
  File "/Users/tmy/Desktop/WatchTogether/venv/lib/python3.11/site-packages/django/db/models/sql/query.py", line 1565, in _add_q
    child_clause, needed_inner = self.build_filter(
                                 ^^^^^^^^^^^^^^^^^^
  File "/Users/tmy/Desktop/WatchTogether/venv/lib/python3.11/site-packages/django/db/models/sql/query.py", line 1480, in build_filter
    condition = self.build_lookup(lookups, col, value)
                ^^^^^^^^^^^^^^^^^^^^^^^^^^^^^^^^^^^^^^
  File "/Users/tmy/Desktop/WatchTogether/venv/lib/python3.11/site-packages/django/db/models/sql/query.py", line 1307, in build_lookup
    lookup = lookup_class(lhs, rhs)
             ^^^^^^^^^^^^^^^^^^^^^^
  File "/Users/tmy/Desktop/WatchTogether/venv/lib/python3.11/site-packages/django/db/models/lookups.py", line 27, in __init__
    self.rhs = self.get_prep_lookup()
               ^^^^^^^^^^^^^^^^^^^^^^
  File "/Users/tmy/Desktop/WatchTogether/venv/lib/python3.11/site-packages/django/db/models/lookups.py", line 341, in get_prep_lookup
    return super().get_prep_lookup()
           ^^^^^^^^^^^^^^^^^^^^^^^^^
  File "/Users/tmy/Desktop/WatchTogether/venv/lib/python3.11/site-packages/django/db/models/lookups.py", line 85, in get_prep_lookup
    return self.lhs.output_field.get_prep_value(self.rhs)
           ^^^^^^^^^^^^^^^^^^^^^^^^^^^^^^^^^^^^^^^^^^^^^^
  File "/Users/tmy/Desktop/WatchTogether/venv/lib/python3.11/site-packages/django/db/models/fields/__init__.py", line 2055, in get_prep_value
    raise e.__class__(
ValueError: Field 'id' expected a number but got 'golqmDIkk'.
2023-07-18 22:09:21,290 django.utils.autoreload INFO     /Users/tmy/Desktop/WatchTogether/users/backend_logic.py changed, reloading.
2023-07-18 22:09:21,477 django.utils.autoreload INFO     Watching for file changes with StatReloader
2023-07-18 22:10:43,375 django.utils.autoreload INFO     /Users/tmy/Desktop/WatchTogether/users/backend_logic.py changed, reloading.
2023-07-18 22:10:43,559 django.utils.autoreload INFO     Watching for file changes with StatReloader
2023-07-18 22:11:05,402 django.utils.autoreload INFO     /Users/tmy/Desktop/WatchTogether/users/backend_logic.py changed, reloading.
2023-07-18 22:11:05,578 django.utils.autoreload INFO     Watching for file changes with StatReloader
2023-07-18 22:11:33,597 django.utils.autoreload INFO     /Users/tmy/Desktop/WatchTogether/users/views.py changed, reloading.
2023-07-18 22:11:33,766 django.utils.autoreload INFO     Watching for file changes with StatReloader
